Workbook

Sheet Test Cases
A1: ID | B1: Module | C1: Role | D1: Steps | E1: Expected Result | F1: Status | G1: Actual Result | H1: Evidence | I1: Defect ID | J1: Tester | K1: Date
A2: LEAD-01 | B2: Leads | C2: Riya RM | D2: Leads > Create Lead; fill every section incl. consent; click Create Lead | E2: Lead opens in state NEW; mobile and email masked | F2: Pass
A3: LEAD-02 | B3: Leads | C3: Riya RM | D3: Submit the create form empty | E3: Required-field messages; no lead created | F3: Pass | G3: Requires Name and contact
A4: LEAD-03 | B4: Leads | C4: Riya RM | D4: Create a lead without consent details | E4: Blocked; consent is mandatory | F4: Pass | G4: Consent is mandatory.
A5: LEAD-04 | B5: Leads | C5: Riya RM | D5: Create a second lead with the same mobile | E5: Duplicate flag ('Dup:') appears on the list | F5: Fail | G5: Expected duplicate flag, got error (Raises Error)
A6: LEAD-05 | B6: Leads | C6: Riya RM | D6: On a NEW lead click Attempt Contact, then Mark In Progress | E6: State NEW > CONTACT_ATTEMPTED > IN_PROGRESS; Contact Attempts shows 1 | F6: Pass
A7: LEAD-06 | B7: Leads | C7: Riya RM | D7: Qualify Lead with applicant type and amount blank | E7: Validation error; state unchanged | F7: Fail | G7: [Re-run required - invalid text System.Xml.XmlElement / blank income accepted]
A8: LEAD-07 | B8: Leads | C8: Riya RM | D8: Qualify with valid data, then Convert to Loan Application | E8: QUALIFIED then CONVERTED; customer and application numbers shown; action buttons gone | F8: Pass | G8: (add requested amount dynamically)
A9: LEAD-08 | B9: Leads | C9: Riya RM | D9: On a converted lead try to qualify or disqualify | E9: Not allowed (terminal state) | F9: Pass
A10: LEAD-09 | B10: Leads | C10: Riya RM | D10: Disqualify a lead, then reopen it with a reason | E10: DISQUALIFIED, then back to NEW; reopen needs a reason code | F10: Fail | G10: Once lead is disqualified, the status cannot be altered. (we should be able to reopen the case )
A11: LEAD-10 | B11: Leads | C11: Riya RM | D11: Filter the list by state, then Reset | E11: List filters and resets; pagination still works | F11: Pass
A12: LEAD-11 | B12: Leads | C12: Two testers | D12: Open the same lead in two tabs and change state in both | E12: Second save rejected (version conflict), not silently overwritten | F12: Not Run
A13: CONS-01 | B13: Consent | C13: Riya RM | D13: Open /customers/<id>/consents; Record New Consent, purpose SHARE_WITH_LENDER | E13: Target field appears and is required; row shows ACTIVE | F13: Pass
A14: CONS-02 | B14: Consent | C14: Riya RM | D14: Withdraw a consent | E14: Status changes, button disappears, record stays | F14: Pass
A15: TASK-01 | B15: Tasks | C15: Riya RM | D15: Create Task linked to a lead, with priority and SLA class | E15: Task appears in Mine and All Visible | F15: Fail | G15: A record with the same unique value already exists.
A16: TASK-02 | B16: Tasks | C16: Riya RM | D16: Check the Mine tab after TASK-01 (code hard-codes owner 'usr_me', audit AUD-005) | E16: Task appears under the logged-in user | F16: Not Run
A17: TASK-03 | B17: Tasks | C17: Riya RM | D17: Complete a task with an outcome and note | E17: Status Completed; gone from Open filter | F17: Not Run
A18: MSG-01 | B18: Messaging | C18: Asha Admin | D18: New Template; Save & Approve Template | E18: Row with APPROVED chip | F18: Pass
A19: MSG-02 | B19: Messaging | C19: Asha Admin | D19: Template body using {{var}} not declared | E19: Live preview and validation flag the variable | F19: Fail | G19: Templeate getting approved even without the declared variables ( Also the templates cannot e modified or even altered)
A20: MSG-03 | B20: Messaging | C20: Asha Admin | D20: Dispatch tab: pick lead, template, variables; Dispatch Message | E20: In this build a red SEND_BLOCKED with reason code (no provider). Success is a defect | F20: Fail | G20: Expected a blocked send, got Message Successfully Sent!
A21: MSG-04 | B21: Messaging | C21: Asha Admin | D21: Dispatch outside 09:00-21:00, and for a customer with consent withdrawn | E21: Blocked with the matching reason, never delivered | F21: Fail | G21: Messages are getting sent without
A22: CMP-01 | B22: Complaints | C22: Riya RM | D22: Record complaint with valid text | E22: Acknowledgement reference shown | F22: Fail | G22: Complainant not found. (ref 01M5F0NSC6M59Q5NMRRS724RCH)
A23: CMP-02 | B23: Complaints | C23: Riya RM | D23: Enter under 10 characters, then text with a PAN-like or 12-digit number | E23: Both rejected | F23: Fail | G23: [Re-run required - invalid text Recipient Masked:]
A24: CMP-03 | B24: Complaints | C24: Asha Admin | D24: Assign owner and due date; Start work; refer to lender; Resolve complaint | E24: In progress, then Resolved; read-only until reopened | F24: Not Run | G24: [Re-run required - invalid text 9876****212]
A25: CMP-04 | B25: Complaints | C25: Asha Admin | D25: Reopen complaint with a reason | E25: Resolution cleared; reason kept in audit | F25: Not Run | G25: [Re-run required - invalid text • Provider:]
A26: LND-01 | B26: Lenders | C26: Asha Admin | D26: New lender; add an empanelment and a contact | E26: All three save and show on the lender page | F26: Pass | G26: (Check weather we need to uplaod any documents and if yes add option to do so. )
A27: LND-02 | B27: Lenders | C27: Asha Admin | D27: Change lender status to Paused or Terminated without a reason | E27: Reason is required | F27: Fail | G27: [Re-run required - invalid text System.Xml.XmlElement / status change without reason]
A28: LND-03 | B28: Lenders | C28: Asha Admin | D28: Add a product, then New version with min amount above max | E28: Rejected | F28: Not Run
A29: LND-04 | B29: Lenders | C29: Asha Admin | D29: Add a second terms version | E29: Old version kept; new version marked In force | F29: Not Run
A30: ADM-01 | B30: Admin | C30: Asha Admin | D30: Create a branch, queue and team; add members to the queue | E30: Saved; branch code cannot be changed afterwards | F30: Not Run
A31: ADM-02 | B31: Admin | C31: Asha Admin | D31: Configuration: set routing mode, SLA, business hours; Save Configuration | E31: 'Configuration successfully updated.'; values persist after refresh | F31: Not Run
A32: ADM-03 | B32: Admin | C32: Asha Admin | D32: Set business hours end earlier than start | E32: Should be rejected; if saved, log a defect | F32: Not Run
A33: USR-01 | B33: Users | C33: Asha Admin | D33: Create a staff user with a role | E33: User appears in directory; counts update | F33: Not Run
A34: USR-02 | B34: Users | C34: Asha Admin | D34: Create a custom role with a few permissions | E34: Shows as Custom Role; matrix reflects the choice | F34: Not Run
A35: RBAC-01 | B35: Access | C35: Sameer Sales | D35: Sign in and scan the sidebar | E35: No Administration group | F35: Not Run
A36: RBAC-02 | B36: Access | C36: Sameer Sales | D36: Paste an admin URL such as /users or the configuration page | E36: Access denied or redirect; API returns 403 in Network tab | F36: Not Run
A37: RBAC-03 | B37: Access | C37: Sameer Sales | D37: Open a lead that belongs to another branch | E37: Not found (404), not the lead's data | F37: Not Run
A38: AUTH-01 | B38: Sign-in | C38: Any | D38: Sign in with a wrong password | E38: Generic error; no hint which part was wrong | F38: Not Run
A39: AUTH-02 | B39: Sign-in | C39: Any | D39: Sign in, enter a wrong then a correct 6-digit code | E39: Wrong code rejected; correct code lands on Home | F39: Not Run
... A50: RBAC-05 | B50: Access | C50: Sameer Sales | D50: Attempt newly guarded actions (commission.calculate, lender.manage, product.manage) | E50: Zero-permission user blocked; old fallback role and new designated role allowed | F50: Not Run
...

Sheet Legend
A1: DSA-Agent Manual Test Plan - how to use
A3: 1. Run each case on the 'Test Cases' sheet as the role named in the Role column, using synthetic data only.
A4: 2. Fill the yellow columns: Status (dropdown), Actual Result, Evidence, Defect ID, Tester, Date.
A5: 3. On every Fail attach a screenshot, the exact error text and the Network-tab status code. Never paste tokens or real personal data.
A6: 4. Status values: Not Run, Pass, Fail, Blocked. The 'Summary' sheet counts them automatically.
A7: 5. Demo roles & accounts: Asha Admin (admin@alpha.com / ROLE-TENANT-ADMIN), Riya RM (rm1@alpha.com / ROLE-RM), Sameer Sales (sales1@alpha.com / ROLE-SALES-EXEC).
A8: Source: cases derived from the DSA-Agent UI labels and the read-only audit; AUD-xxx IDs refer to that audit report.

Sheet Summary
A1: Status | B1: Count | C1: Share
A2: Pass | B2: =COUNTIF('Test Cases'!$F$2:$F$52,A2) | C2: =IFERROR(B2/$B$6,0)
A3: Fail | B3: =COUNTIF('Test Cases'!$F$2:$F$52,A3) | C3: =IFERROR(B3/$B$6,0)
A4: Blocked | B4: =COUNTIF('Test Cases'!$F$2:$F$52,A4) | C4: =IFERROR(B4/$B$6,0)
A5: Not Run | B5: =COUNTIF('Test Cases'!$F$2:$F$52,A5) | C5: =IFERROR(B5/$B$6,0)
A6: Total | B6: =SUM(B2:B5) | C6: =IFERROR(SUM(C2:C5),0)
A8: Cases by module | B8: Cases | C8: Failed
A9: Leads | B9: =COUNTIF('Test Cases'!$B$2:$B$52,A9) | C9: =COUNTIFS('Test Cases'!$B$2:$B$52,A9,'Test Cases'!$F$2:$F$52,"Fail")
A10: Consent | B10: =COUNTIF('Test Cases'!$B$2:$B$52,A10) | C10: =COUNTIFS('Test Cases'!$B$2:$B$52,A10,'Test Cases'!$F$2:$F$52,"Fail")
A11: Tasks | B11: =COUNTIF('Test Cases'!$B$2:$B$52,A11) | C11: =COUNTIFS('Test Cases'!$B$2:$B$52,A11,'Test Cases'!$F$2:$F$52,"Fail")
A12: Messaging | B12: =COUNTIF('Test Cases'!$B$2:$B$52,A12) | C12: =COUNTIFS('Test Cases'!$B$2:$B$52,A12,'Test Cases'!$F$2:$F$52,"Fail")
A13: Complaints | B13: =COUNTIF('Test Cases'!$B$2:$B$52,A13) | C13: =COUNTIFS('Test Cases'!$B$2:$B$52,A13,'Test Cases'!$F$2:$F$52,"Fail")
A14: Lenders | B14: =COUNTIF('Test Cases'!$B$2:$B$52,A14) | C14: =COUNTIFS('Test Cases'!$B$2:$B$52,A14,'Test Cases'!$F$2:$F$52,"Fail")
A15: Admin | B15: =COUNTIF('Test Cases'!$B$2:$B$52,A15) | C15: =COUNTIFS('Test Cases'!$B$2:$B$52,A15,'Test Cases'!$F$2:$F$52,"Fail")
A16: Users | B16: =COUNTIF('Test Cases'!$B$2:$B$52,A16) | C16: =COUNTIFS('Test Cases'!$B$2:$B$52,A16,'Test Cases'!$F$2:$F$52,"Fail")
A17: Access | B17: =COUNTIF('Test Cases'!$B$2:$B$52,A17) | C17: =COUNTIFS('Test Cases'!$B$2:$B$52,A17,'Test Cases'!$F$2:$F$52,"Fail")
A18: Sign-in | B18: =COUNTIF('Test Cases'!$B$2:$B$52,A18) | C18: =COUNTIFS('Test Cases'!$B$2:$B$52,A18,'Test Cases'!$F$2:$F$52,"Fail")
A19: Notifications | B19: =COUNTIF('Test Cases'!$B$2:$B$52,A19) | C19: =COUNTIFS('Test Cases'!$B$2:$B$52,A19,'Test Cases'!$F$2:$F$52,"Fail")
A20: UI/UX | B20: =COUNTIF('Test Cases'!$B$2:$B$52,A20) | C20: =COUNTIFS('Test Cases'!$B$2:$B$52,A20,'Test Cases'!$F$2:$F$52,"Fail")
